SIGINT/SIGQUIT received...killing workers...
worker 1 buried after 1 seconds
goodbye to uWSGI.
VACUUM: pidfile removed.
*** Starting uWSGI 2.0.18 (64bit) on [Fri May  8 22:32:27 2020] ***
compiled with version: 8.3.1 20190507 (Red Hat 8.3.1-4) on 04 May 2020 16:35:18
os: Linux-4.18.0-147.5.1.el8_1.x86_64 #1 SMP Wed Feb 5 02:00:39 UTC 2020
nodename: iZ8vb3ysk1dlatpqbiit08Z
machine: x86_64
clock source: unix
detected number of CPU cores: 2
current working directory: /root/jarvis/deployment/dongqiudi
writing pidfile to /root/jarvis/deployment/dongqiudi/pid/uwsgi-8080.pid
detected binary path: /usr/local/bin/uwsgi
!!! no internal routing support, rebuild with pcre support !!!
uWSGI running as root, you can use --uid/--gid/--chroot options
*** WARNING: you are running uWSGI as root !!! (use the --uid flag) *** 
chdir() to /root/jarvis/deployment/dongqiudi
your processes number limit is 15002
your memory page size is 4096 bytes
detected max file descriptor number: 65535
lock engine: pthread robust mutexes
thunder lock: disabled (you can enable it with --thunder-lock)
uwsgi socket 0 bound to TCP address :8080 fd 9
uWSGI running as root, you can use --uid/--gid/--chroot options
*** WARNING: you are running uWSGI as root !!! (use the --uid flag) *** 
Python version: 3.6.8 (default, Nov 21 2019, 19:31:34)  [GCC 8.3.1 20190507 (Red Hat 8.3.1-4)]
Python main interpreter initialized at 0x992230
uWSGI running as root, you can use --uid/--gid/--chroot options
*** WARNING: you are running uWSGI as root !!! (use the --uid flag) *** 
python threads support enabled
your server socket listen backlog is limited to 100 connections
your mercy for graceful operations on workers is 60 seconds
mapped 145808 bytes (142 KB) for 1 cores
*** Operational MODE: single process ***
{'a': 1}
WSGI app 0 (mountpoint='') ready in 0 seconds on interpreter 0x992230 pid: 32059 (default app)
uWSGI running as root, you can use --uid/--gid/--chroot options
*** WARNING: you are running uWSGI as root !!! (use the --uid flag) *** 
*** uWSGI is running in multiple interpreter mode ***
spawned uWSGI master process (pid: 32059)
spawned uWSGI worker 1 (pid: 32061, cores: 1)
Traceback (most recent call last):
  File "/usr/local/lib/python3.6/site-packages/django/core/handlers/exception.py", line 35, in inner
    response = get_response(request)
  File "/usr/local/lib/python3.6/site-packages/django/core/handlers/base.py", line 113, in _get_response
    resolver_match = resolver.resolve(request.path_info)
  File "/usr/local/lib/python3.6/site-packages/django/urls/resolvers.py", line 494, in resolve
    for pattern in self.url_patterns:
  File "/usr/local/lib/python3.6/site-packages/django/utils/functional.py", line 36, in __get__
    res = instance.__dict__[self.name] = self.func(instance)
  File "/usr/local/lib/python3.6/site-packages/django/urls/resolvers.py", line 536, in url_patterns
    patterns = getattr(self.urlconf_module, "urlpatterns", self.urlconf_module)
  File "/usr/local/lib/python3.6/site-packages/django/utils/functional.py", line 36, in __get__
    res = instance.__dict__[self.name] = self.func(instance)
  File "/usr/local/lib/python3.6/site-packages/django/urls/resolvers.py", line 529, in urlconf_module
    return import_module(self.urlconf_name)
  File "/usr/lib64/python3.6/importlib/__init__.py", line 126, in import_module
    return _bootstrap._gcd_import(name[level:], package, level)
  File "<frozen importlib._bootstrap>", line 994, in _gcd_import
  File "<frozen importlib._bootstrap>", line 971, in _find_and_load
  File "<frozen importlib._bootstrap>", line 955, in _find_and_load_unlocked
  File "<frozen importlib._bootstrap>", line 665, in _load_unlocked
  File "<frozen importlib._bootstrap_external>", line 674, in exec_module
  File "<frozen importlib._bootstrap_external>", line 781, in get_code
  File "<frozen importlib._bootstrap_external>", line 741, in source_to_code
  File "<frozen importlib._bootstrap>", line 219, in _call_with_frames_removed
  File "./dongqiudi/urls.py", line 22
    path('/.well-known/pki-validation/',include('backend.urls'))
       ^
SyntaxError: invalid syntax

During handling of the above exception, another exception occurred:

Traceback (most recent call last):
  File "/usr/local/lib/python3.6/site-packages/django/core/handlers/exception.py", line 35, in inner
    response = get_response(request)
  File "/usr/local/lib/python3.6/site-packages/django/utils/deprecation.py", line 95, in __call__
    response = self.get_response(request)
  File "/usr/local/lib/python3.6/site-packages/django/core/handlers/exception.py", line 37, in inner
    response = response_for_exception(request, exc)
  File "/usr/local/lib/python3.6/site-packages/django/core/handlers/exception.py", line 87, in response_for_exception
    response = handle_uncaught_exception(request, get_resolver(get_urlconf()), sys.exc_info())
  File "/usr/local/lib/python3.6/site-packages/django/core/handlers/exception.py", line 125, in handle_uncaught_exception
    callback, param_dict = resolver.resolve_error_handler(500)
  File "/usr/local/lib/python3.6/site-packages/django/urls/resolvers.py", line 549, in resolve_error_handler
    callback = getattr(self.urlconf_module, 'handler%s' % view_type, None)
  File "/usr/local/lib/python3.6/site-packages/django/utils/functional.py", line 36, in __get__
    res = instance.__dict__[self.name] = self.func(instance)
  File "/usr/local/lib/python3.6/site-packages/django/urls/resolvers.py", line 529, in urlconf_module
    return import_module(self.urlconf_name)
  File "/usr/lib64/python3.6/importlib/__init__.py", line 126, in import_module
    return _bootstrap._gcd_import(name[level:], package, level)
  File "<frozen importlib._bootstrap>", line 994, in _gcd_import
  File "<frozen importlib._bootstrap>", line 971, in _find_and_load
  File "<frozen importlib._bootstrap>", line 955, in _find_and_load_unlocked
  File "<frozen importlib._bootstrap>", line 665, in _load_unlocked
  File "<frozen importlib._bootstrap_external>", line 674, in exec_module
  File "<frozen importlib._bootstrap_external>", line 781, in get_code
  File "<frozen importlib._bootstrap_external>", line 741, in source_to_code
  File "<frozen importlib._bootstrap>", line 219, in _call_with_frames_removed
  File "./dongqiudi/urls.py", line 22
    path('/.well-known/pki-validation/',include('backend.urls'))
       ^
SyntaxError: invalid syntax

During handling of the above exception, another exception occurred:

Traceback (most recent call last):
  File "/usr/local/lib/python3.6/site-packages/django/core/handlers/exception.py", line 35, in inner
    response = get_response(request)
  File "/usr/local/lib/python3.6/site-packages/django/utils/deprecation.py", line 95, in __call__
    response = self.get_response(request)
  File "/usr/local/lib/python3.6/site-packages/django/core/handlers/exception.py", line 37, in inner
    response = response_for_exception(request, exc)
  File "/usr/local/lib/python3.6/site-packages/django/core/handlers/exception.py", line 87, in response_for_exception
    response = handle_uncaught_exception(request, get_resolver(get_urlconf()), sys.exc_info())
  File "/usr/local/lib/python3.6/site-packages/django/core/handlers/exception.py", line 125, in handle_uncaught_exception
    callback, param_dict = resolver.resolve_error_handler(500)
  File "/usr/local/lib/python3.6/site-packages/django/urls/resolvers.py", line 549, in resolve_error_handler
    callback = getattr(self.urlconf_module, 'handler%s' % view_type, None)
  File "/usr/local/lib/python3.6/site-packages/django/utils/functional.py", line 36, in __get__
    res = instance.__dict__[self.name] = self.func(instance)
  File "/usr/local/lib/python3.6/site-packages/django/urls/resolvers.py", line 529, in urlconf_module
    return import_module(self.urlconf_name)
  File "/usr/lib64/python3.6/importlib/__init__.py", line 126, in import_module
    return _bootstrap._gcd_import(name[level:], package, level)
  File "<frozen importlib._bootstrap>", line 994, in _gcd_import
  File "<frozen importlib._bootstrap>", line 971, in _find_and_load
  File "<frozen importlib._bootstrap>", line 955, in _find_and_load_unlocked
  File "<frozen importlib._bootstrap>", line 665, in _load_unlocked
  File "<frozen importlib._bootstrap_external>", line 674, in exec_module
  File "<frozen importlib._bootstrap_external>", line 781, in get_code
  File "<frozen importlib._bootstrap_external>", line 741, in source_to_code
  File "<frozen importlib._bootstrap>", line 219, in _call_with_frames_removed
  File "./dongqiudi/urls.py", line 22
    path('/.well-known/pki-validation/',include('backend.urls'))
       ^
SyntaxError: invalid syntax

During handling of the above exception, another exception occurred:

Traceback (most recent call last):
  File "/usr/local/lib/python3.6/site-packages/django/core/handlers/exception.py", line 35, in inner
    response = get_response(request)
  File "/usr/local/lib/python3.6/site-packages/django/utils/deprecation.py", line 95, in __call__
    response = self.get_response(request)
  File "/usr/local/lib/python3.6/site-packages/django/core/handlers/exception.py", line 37, in inner
    response = response_for_exception(request, exc)
  File "/usr/local/lib/python3.6/site-packages/django/core/handlers/exception.py", line 87, in response_for_exception
    response = handle_uncaught_exception(request, get_resolver(get_urlconf()), sys.exc_info())
  File "/usr/local/lib/python3.6/site-packages/django/core/handlers/exception.py", line 125, in handle_uncaught_exception
    callback, param_dict = resolver.resolve_error_handler(500)
  File "/usr/local/lib/python3.6/site-packages/django/urls/resolvers.py", line 549, in resolve_error_handler
    callback = getattr(self.urlconf_module, 'handler%s' % view_type, None)
  File "/usr/local/lib/python3.6/site-packages/django/utils/functional.py", line 36, in __get__
    res = instance.__dict__[self.name] = self.func(instance)
  File "/usr/local/lib/python3.6/site-packages/django/urls/resolvers.py", line 529, in urlconf_module
    return import_module(self.urlconf_name)
  File "/usr/lib64/python3.6/importlib/__init__.py", line 126, in import_module
    return _bootstrap._gcd_import(name[level:], package, level)
  File "<frozen importlib._bootstrap>", line 994, in _gcd_import
  File "<frozen importlib._bootstrap>", line 971, in _find_and_load
  File "<frozen importlib._bootstrap>", line 955, in _find_and_load_unlocked
  File "<frozen importlib._bootstrap>", line 665, in _load_unlocked
  File "<frozen importlib._bootstrap_external>", line 674, in exec_module
  File "<frozen importlib._bootstrap_external>", line 781, in get_code
  File "<frozen importlib._bootstrap_external>", line 741, in source_to_code
  File "<frozen importlib._bootstrap>", line 219, in _call_with_frames_removed
  File "./dongqiudi/urls.py", line 22
    path('/.well-known/pki-validation/',include('backend.urls'))
       ^
SyntaxError: invalid syntax

During handling of the above exception, another exception occurred:

Traceback (most recent call last):
  File "/usr/local/lib/python3.6/site-packages/django/core/handlers/exception.py", line 35, in inner
    response = get_response(request)
  File "/usr/local/lib/python3.6/site-packages/django/utils/deprecation.py", line 95, in __call__
    response = self.get_response(request)
  File "/usr/local/lib/python3.6/site-packages/django/core/handlers/exception.py", line 37, in inner
    response = response_for_exception(request, exc)
  File "/usr/local/lib/python3.6/site-packages/django/core/handlers/exception.py", line 87, in response_for_exception
    response = handle_uncaught_exception(request, get_resolver(get_urlconf()), sys.exc_info())
  File "/usr/local/lib/python3.6/site-packages/django/core/handlers/exception.py", line 125, in handle_uncaught_exception
    callback, param_dict = resolver.resolve_error_handler(500)
  File "/usr/local/lib/python3.6/site-packages/django/urls/resolvers.py", line 549, in resolve_error_handler
    callback = getattr(self.urlconf_module, 'handler%s' % view_type, None)
  File "/usr/local/lib/python3.6/site-packages/django/utils/functional.py", line 36, in __get__
    res = instance.__dict__[self.name] = self.func(instance)
  File "/usr/local/lib/python3.6/site-packages/django/urls/resolvers.py", line 529, in urlconf_module
    return import_module(self.urlconf_name)
  File "/usr/lib64/python3.6/importlib/__init__.py", line 126, in import_module
    return _bootstrap._gcd_import(name[level:], package, level)
  File "<frozen importlib._bootstrap>", line 994, in _gcd_import
  File "<frozen importlib._bootstrap>", line 971, in _find_and_load
  File "<frozen importlib._bootstrap>", line 955, in _find_and_load_unlocked
  File "<frozen importlib._bootstrap>", line 665, in _load_unlocked
  File "<frozen importlib._bootstrap_external>", line 674, in exec_module
  File "<frozen importlib._bootstrap_external>", line 781, in get_code
  File "<frozen importlib._bootstrap_external>", line 741, in source_to_code
  File "<frozen importlib._bootstrap>", line 219, in _call_with_frames_removed
  File "./dongqiudi/urls.py", line 22
    path('/.well-known/pki-validation/',include('backend.urls'))
       ^
SyntaxError: invalid syntax

During handling of the above exception, another exception occurred:

Traceback (most recent call last):
  File "/usr/local/lib/python3.6/site-packages/django/core/handlers/exception.py", line 35, in inner
    response = get_response(request)
  File "/usr/local/lib/python3.6/site-packages/django/utils/deprecation.py", line 95, in __call__
    response = self.get_response(request)
  File "/usr/local/lib/python3.6/site-packages/django/core/handlers/exception.py", line 37, in inner
    response = response_for_exception(request, exc)
  File "/usr/local/lib/python3.6/site-packages/django/core/handlers/exception.py", line 87, in response_for_exception
    response = handle_uncaught_exception(request, get_resolver(get_urlconf()), sys.exc_info())
  File "/usr/local/lib/python3.6/site-packages/django/core/handlers/exception.py", line 125, in handle_uncaught_exception
    callback, param_dict = resolver.resolve_error_handler(500)
  File "/usr/local/lib/python3.6/site-packages/django/urls/resolvers.py", line 549, in resolve_error_handler
    callback = getattr(self.urlconf_module, 'handler%s' % view_type, None)
  File "/usr/local/lib/python3.6/site-packages/django/utils/functional.py", line 36, in __get__
    res = instance.__dict__[self.name] = self.func(instance)
  File "/usr/local/lib/python3.6/site-packages/django/urls/resolvers.py", line 529, in urlconf_module
    return import_module(self.urlconf_name)
  File "/usr/lib64/python3.6/importlib/__init__.py", line 126, in import_module
    return _bootstrap._gcd_import(name[level:], package, level)
  File "<frozen importlib._bootstrap>", line 994, in _gcd_import
  File "<frozen importlib._bootstrap>", line 971, in _find_and_load
  File "<frozen importlib._bootstrap>", line 955, in _find_and_load_unlocked
  File "<frozen importlib._bootstrap>", line 665, in _load_unlocked
  File "<frozen importlib._bootstrap_external>", line 674, in exec_module
  File "<frozen importlib._bootstrap_external>", line 781, in get_code
  File "<frozen importlib._bootstrap_external>", line 741, in source_to_code
  File "<frozen importlib._bootstrap>", line 219, in _call_with_frames_removed
  File "./dongqiudi/urls.py", line 22
    path('/.well-known/pki-validation/',include('backend.urls'))
       ^
SyntaxError: invalid syntax

During handling of the above exception, another exception occurred:

Traceback (most recent call last):
  File "/usr/local/lib/python3.6/site-packages/django/core/handlers/exception.py", line 35, in inner
    response = get_response(request)
  File "/usr/local/lib/python3.6/site-packages/django/utils/deprecation.py", line 95, in __call__
    response = self.get_response(request)
  File "/usr/local/lib/python3.6/site-packages/django/core/handlers/exception.py", line 37, in inner
    response = response_for_exception(request, exc)
  File "/usr/local/lib/python3.6/site-packages/django/core/handlers/exception.py", line 87, in response_for_exception
    response = handle_uncaught_exception(request, get_resolver(get_urlconf()), sys.exc_info())
  File "/usr/local/lib/python3.6/site-packages/django/core/handlers/exception.py", line 125, in handle_uncaught_exception
    callback, param_dict = resolver.resolve_error_handler(500)
  File "/usr/local/lib/python3.6/site-packages/django/urls/resolvers.py", line 549, in resolve_error_handler
    callback = getattr(self.urlconf_module, 'handler%s' % view_type, None)
  File "/usr/local/lib/python3.6/site-packages/django/utils/functional.py", line 36, in __get__
    res = instance.__dict__[self.name] = self.func(instance)
  File "/usr/local/lib/python3.6/site-packages/django/urls/resolvers.py", line 529, in urlconf_module
    return import_module(self.urlconf_name)
  File "/usr/lib64/python3.6/importlib/__init__.py", line 126, in import_module
    return _bootstrap._gcd_import(name[level:], package, level)
  File "<frozen importlib._bootstrap>", line 994, in _gcd_import
  File "<frozen importlib._bootstrap>", line 971, in _find_and_load
  File "<frozen importlib._bootstrap>", line 955, in _find_and_load_unlocked
  File "<frozen importlib._bootstrap>", line 665, in _load_unlocked
  File "<frozen importlib._bootstrap_external>", line 674, in exec_module
  File "<frozen importlib._bootstrap_external>", line 781, in get_code
  File "<frozen importlib._bootstrap_external>", line 741, in source_to_code
  File "<frozen importlib._bootstrap>", line 219, in _call_with_frames_removed
  File "./dongqiudi/urls.py", line 22
    path('/.well-known/pki-validation/',include('backend.urls'))
       ^
SyntaxError: invalid syntax

During handling of the above exception, another exception occurred:

Traceback (most recent call last):
  File "/usr/local/lib/python3.6/site-packages/django/core/handlers/wsgi.py", line 146, in __call__
    response = self.get_response(request)
  File "/usr/local/lib/python3.6/site-packages/django/core/handlers/base.py", line 81, in get_response
    response = self._middleware_chain(request)
  File "/usr/local/lib/python3.6/site-packages/django/core/handlers/exception.py", line 37, in inner
    response = response_for_exception(request, exc)
  File "/usr/local/lib/python3.6/site-packages/django/core/handlers/exception.py", line 87, in response_for_exception
    response = handle_uncaught_exception(request, get_resolver(get_urlconf()), sys.exc_info())
  File "/usr/local/lib/python3.6/site-packages/django/core/handlers/exception.py", line 125, in handle_uncaught_exception
    callback, param_dict = resolver.resolve_error_handler(500)
  File "/usr/local/lib/python3.6/site-packages/django/urls/resolvers.py", line 549, in resolve_error_handler
    callback = getattr(self.urlconf_module, 'handler%s' % view_type, None)
  File "/usr/local/lib/python3.6/site-packages/django/utils/functional.py", line 36, in __get__
    res = instance.__dict__[self.name] = self.func(instance)
  File "/usr/local/lib/python3.6/site-packages/django/urls/resolvers.py", line 529, in urlconf_module
    return import_module(self.urlconf_name)
  File "/usr/lib64/python3.6/importlib/__init__.py", line 126, in import_module
    return _bootstrap._gcd_import(name[level:], package, level)
  File "<frozen importlib._bootstrap>", line 994, in _gcd_import
  File "<frozen importlib._bootstrap>", line 971, in _find_and_load
  File "<frozen importlib._bootstrap>", line 955, in _find_and_load_unlocked
  File "<frozen importlib._bootstrap>", line 665, in _load_unlocked
  File "<frozen importlib._bootstrap_external>", line 674, in exec_module
  File "<frozen importlib._bootstrap_external>", line 781, in get_code
  File "<frozen importlib._bootstrap_external>", line 741, in source_to_code
  File "<frozen importlib._bootstrap>", line 219, in _call_with_frames_removed
  File "./dongqiudi/urls.py", line 22
    path('/.well-known/pki-validation/',include('backend.urls'))
       ^
SyntaxError: invalid syntax
[pid: 32061|app: 0|req: 1/1] 127.0.0.1 () {36 vars in 511 bytes} [Fri May  8 14:33:19 2020] GET /api/v1.0/slide_show/ => generated 0 bytes in 169 msecs (HTTP/1.0 500) 0 headers in 0 bytes (0 switches on core 0)
Traceback (most recent call last):
  File "/usr/local/lib/python3.6/site-packages/django/core/handlers/exception.py", line 35, in inner
    response = get_response(request)
  File "/usr/local/lib/python3.6/site-packages/django/core/handlers/base.py", line 113, in _get_response
    resolver_match = resolver.resolve(request.path_info)
  File "/usr/local/lib/python3.6/site-packages/django/urls/resolvers.py", line 494, in resolve
    for pattern in self.url_patterns:
  File "/usr/local/lib/python3.6/site-packages/django/utils/functional.py", line 36, in __get__
    res = instance.__dict__[self.name] = self.func(instance)
  File "/usr/local/lib/python3.6/site-packages/django/urls/resolvers.py", line 536, in url_patterns
    patterns = getattr(self.urlconf_module, "urlpatterns", self.urlconf_module)
  File "/usr/local/lib/python3.6/site-packages/django/utils/functional.py", line 36, in __get__
    res = instance.__dict__[self.name] = self.func(instance)
  File "/usr/local/lib/python3.6/site-packages/django/urls/resolvers.py", line 529, in urlconf_module
    return import_module(self.urlconf_name)
  File "/usr/lib64/python3.6/importlib/__init__.py", line 126, in import_module
    return _bootstrap._gcd_import(name[level:], package, level)
  File "<frozen importlib._bootstrap>", line 994, in _gcd_import
  File "<frozen importlib._bootstrap>", line 971, in _find_and_load
  File "<frozen importlib._bootstrap>", line 955, in _find_and_load_unlocked
  File "<frozen importlib._bootstrap>", line 665, in _load_unlocked
  File "<frozen importlib._bootstrap_external>", line 674, in exec_module
  File "<frozen importlib._bootstrap_external>", line 781, in get_code
  File "<frozen importlib._bootstrap_external>", line 741, in source_to_code
  File "<frozen importlib._bootstrap>", line 219, in _call_with_frames_removed
  File "./dongqiudi/urls.py", line 22
    path('/.well-known/pki-validation/',include('backend.urls'))
       ^
SyntaxError: invalid syntax

During handling of the above exception, another exception occurred:

Traceback (most recent call last):
  File "/usr/local/lib/python3.6/site-packages/django/core/handlers/exception.py", line 35, in inner
    response = get_response(request)
  File "/usr/local/lib/python3.6/site-packages/django/utils/deprecation.py", line 95, in __call__
    response = self.get_response(request)
  File "/usr/local/lib/python3.6/site-packages/django/core/handlers/exception.py", line 37, in inner
    response = response_for_exception(request, exc)
  File "/usr/local/lib/python3.6/site-packages/django/core/handlers/exception.py", line 87, in response_for_exception
    response = handle_uncaught_exception(request, get_resolver(get_urlconf()), sys.exc_info())
  File "/usr/local/lib/python3.6/site-packages/django/core/handlers/exception.py", line 125, in handle_uncaught_exception
    callback, param_dict = resolver.resolve_error_handler(500)
  File "/usr/local/lib/python3.6/site-packages/django/urls/resolvers.py", line 549, in resolve_error_handler
    callback = getattr(self.urlconf_module, 'handler%s' % view_type, None)
  File "/usr/local/lib/python3.6/site-packages/django/utils/functional.py", line 36, in __get__
    res = instance.__dict__[self.name] = self.func(instance)
  File "/usr/local/lib/python3.6/site-packages/django/urls/resolvers.py", line 529, in urlconf_module
    return import_module(self.urlconf_name)
  File "/usr/lib64/python3.6/importlib/__init__.py", line 126, in import_module
    return _bootstrap._gcd_import(name[level:], package, level)
  File "<frozen importlib._bootstrap>", line 994, in _gcd_import
  File "<frozen importlib._bootstrap>", line 971, in _find_and_load
  File "<frozen importlib._bootstrap>", line 955, in _find_and_load_unlocked
  File "<frozen importlib._bootstrap>", line 665, in _load_unlocked
  File "<frozen importlib._bootstrap_external>", line 674, in exec_module
  File "<frozen importlib._bootstrap_external>", line 781, in get_code
  File "<frozen importlib._bootstrap_external>", line 741, in source_to_code
  File "<frozen importlib._bootstrap>", line 219, in _call_with_frames_removed
  File "./dongqiudi/urls.py", line 22
    path('/.well-known/pki-validation/',include('backend.urls'))
       ^
SyntaxError: invalid syntax

During handling of the above exception, another exception occurred:

Traceback (most recent call last):
  File "/usr/local/lib/python3.6/site-packages/django/core/handlers/exception.py", line 35, in inner
    response = get_response(request)
  File "/usr/local/lib/python3.6/site-packages/django/utils/deprecation.py", line 95, in __call__
    response = self.get_response(request)
  File "/usr/local/lib/python3.6/site-packages/django/core/handlers/exception.py", line 37, in inner
    response = response_for_exception(request, exc)
  File "/usr/local/lib/python3.6/site-packages/django/core/handlers/exception.py", line 87, in response_for_exception
    response = handle_uncaught_exception(request, get_resolver(get_urlconf()), sys.exc_info())
  File "/usr/local/lib/python3.6/site-packages/django/core/handlers/exception.py", line 125, in handle_uncaught_exception
    callback, param_dict = resolver.resolve_error_handler(500)
  File "/usr/local/lib/python3.6/site-packages/django/urls/resolvers.py", line 549, in resolve_error_handler
    callback = getattr(self.urlconf_module, 'handler%s' % view_type, None)
  File "/usr/local/lib/python3.6/site-packages/django/utils/functional.py", line 36, in __get__
    res = instance.__dict__[self.name] = self.func(instance)
  File "/usr/local/lib/python3.6/site-packages/django/urls/resolvers.py", line 529, in urlconf_module
    return import_module(self.urlconf_name)
  File "/usr/lib64/python3.6/importlib/__init__.py", line 126, in import_module
    return _bootstrap._gcd_import(name[level:], package, level)
  File "<frozen importlib._bootstrap>", line 994, in _gcd_import
  File "<frozen importlib._bootstrap>", line 971, in _find_and_load
  File "<frozen importlib._bootstrap>", line 955, in _find_and_load_unlocked
  File "<frozen importlib._bootstrap>", line 665, in _load_unlocked
  File "<frozen importlib._bootstrap_external>", line 674, in exec_module
  File "<frozen importlib._bootstrap_external>", line 781, in get_code
  File "<frozen importlib._bootstrap_external>", line 741, in source_to_code
  File "<frozen importlib._bootstrap>", line 219, in _call_with_frames_removed
  File "./dongqiudi/urls.py", line 22
    path('/.well-known/pki-validation/',include('backend.urls'))
       ^
SyntaxError: invalid syntax

During handling of the above exception, another exception occurred:

Traceback (most recent call last):
  File "/usr/local/lib/python3.6/site-packages/django/core/handlers/exception.py", line 35, in inner
    response = get_response(request)
  File "/usr/local/lib/python3.6/site-packages/django/utils/deprecation.py", line 95, in __call__
    response = self.get_response(request)
  File "/usr/local/lib/python3.6/site-packages/django/core/handlers/exception.py", line 37, in inner
    response = response_for_exception(request, exc)
  File "/usr/local/lib/python3.6/site-packages/django/core/handlers/exception.py", line 87, in response_for_exception
    response = handle_uncaught_exception(request, get_resolver(get_urlconf()), sys.exc_info())
  File "/usr/local/lib/python3.6/site-packages/django/core/handlers/exception.py", line 125, in handle_uncaught_exception
    callback, param_dict = resolver.resolve_error_handler(500)
  File "/usr/local/lib/python3.6/site-packages/django/urls/resolvers.py", line 549, in resolve_error_handler
    callback = getattr(self.urlconf_module, 'handler%s' % view_type, None)
  File "/usr/local/lib/python3.6/site-packages/django/utils/functional.py", line 36, in __get__
    res = instance.__dict__[self.name] = self.func(instance)
  File "/usr/local/lib/python3.6/site-packages/django/urls/resolvers.py", line 529, in urlconf_module
    return import_module(self.urlconf_name)
  File "/usr/lib64/python3.6/importlib/__init__.py", line 126, in import_module
    return _bootstrap._gcd_import(name[level:], package, level)
  File "<frozen importlib._bootstrap>", line 994, in _gcd_import
  File "<frozen importlib._bootstrap>", line 971, in _find_and_load
  File "<frozen importlib._bootstrap>", line 955, in _find_and_load_unlocked
  File "<frozen importlib._bootstrap>", line 665, in _load_unlocked
  File "<frozen importlib._bootstrap_external>", line 674, in exec_module
  File "<frozen importlib._bootstrap_external>", line 781, in get_code
  File "<frozen importlib._bootstrap_external>", line 741, in source_to_code
  File "<frozen importlib._bootstrap>", line 219, in _call_with_frames_removed
  File "./dongqiudi/urls.py", line 22
    path('/.well-known/pki-validation/',include('backend.urls'))
       ^
SyntaxError: invalid syntax

During handling of the above exception, another exception occurred:

Traceback (most recent call last):
  File "/usr/local/lib/python3.6/site-packages/django/core/handlers/exception.py", line 35, in inner
    response = get_response(request)
  File "/usr/local/lib/python3.6/site-packages/django/utils/deprecation.py", line 95, in __call__
    response = self.get_response(request)
  File "/usr/local/lib/python3.6/site-packages/django/core/handlers/exception.py", line 37, in inner
    response = response_for_exception(request, exc)
  File "/usr/local/lib/python3.6/site-packages/django/core/handlers/exception.py", line 87, in response_for_exception
    response = handle_uncaught_exception(request, get_resolver(get_urlconf()), sys.exc_info())
  File "/usr/local/lib/python3.6/site-packages/django/core/handlers/exception.py", line 125, in handle_uncaught_exception
    callback, param_dict = resolver.resolve_error_handler(500)
  File "/usr/local/lib/python3.6/site-packages/django/urls/resolvers.py", line 549, in resolve_error_handler
    callback = getattr(self.urlconf_module, 'handler%s' % view_type, None)
  File "/usr/local/lib/python3.6/site-packages/django/utils/functional.py", line 36, in __get__
    res = instance.__dict__[self.name] = self.func(instance)
  File "/usr/local/lib/python3.6/site-packages/django/urls/resolvers.py", line 529, in urlconf_module
    return import_module(self.urlconf_name)
  File "/usr/lib64/python3.6/importlib/__init__.py", line 126, in import_module
    return _bootstrap._gcd_import(name[level:], package, level)
  File "<frozen importlib._bootstrap>", line 994, in _gcd_import
  File "<frozen importlib._bootstrap>", line 971, in _find_and_load
  File "<frozen importlib._bootstrap>", line 955, in _find_and_load_unlocked
  File "<frozen importlib._bootstrap>", line 665, in _load_unlocked
  File "<frozen importlib._bootstrap_external>", line 674, in exec_module
  File "<frozen importlib._bootstrap_external>", line 781, in get_code
  File "<frozen importlib._bootstrap_external>", line 741, in source_to_code
  File "<frozen importlib._bootstrap>", line 219, in _call_with_frames_removed
  File "./dongqiudi/urls.py", line 22
    path('/.well-known/pki-validation/',include('backend.urls'))
       ^
SyntaxError: invalid syntax

During handling of the above exception, another exception occurred:

Traceback (most recent call last):
  File "/usr/local/lib/python3.6/site-packages/django/core/handlers/exception.py", line 35, in inner
    response = get_response(request)
  File "/usr/local/lib/python3.6/site-packages/django/utils/deprecation.py", line 95, in __call__
    response = self.get_response(request)
  File "/usr/local/lib/python3.6/site-packages/django/core/handlers/exception.py", line 37, in inner
    response = response_for_exception(request, exc)
  File "/usr/local/lib/python3.6/site-packages/django/core/handlers/exception.py", line 87, in response_for_exception
    response = handle_uncaught_exception(request, get_resolver(get_urlconf()), sys.exc_info())
  File "/usr/local/lib/python3.6/site-packages/django/core/handlers/exception.py", line 125, in handle_uncaught_exception
    callback, param_dict = resolver.resolve_error_handler(500)
  File "/usr/local/lib/python3.6/site-packages/django/urls/resolvers.py", line 549, in resolve_error_handler
    callback = getattr(self.urlconf_module, 'handler%s' % view_type, None)
  File "/usr/local/lib/python3.6/site-packages/django/utils/functional.py", line 36, in __get__
    res = instance.__dict__[self.name] = self.func(instance)
  File "/usr/local/lib/python3.6/site-packages/django/urls/resolvers.py", line 529, in urlconf_module
    return import_module(self.urlconf_name)
  File "/usr/lib64/python3.6/importlib/__init__.py", line 126, in import_module
    return _bootstrap._gcd_import(name[level:], package, level)
  File "<frozen importlib._bootstrap>", line 994, in _gcd_import
  File "<frozen importlib._bootstrap>", line 971, in _find_and_load
  File "<frozen importlib._bootstrap>", line 955, in _find_and_load_unlocked
  File "<frozen importlib._bootstrap>", line 665, in _load_unlocked
  File "<frozen importlib._bootstrap_external>", line 674, in exec_module
  File "<frozen importlib._bootstrap_external>", line 781, in get_code
  File "<frozen importlib._bootstrap_external>", line 741, in source_to_code
  File "<frozen importlib._bootstrap>", line 219, in _call_with_frames_removed
  File "./dongqiudi/urls.py", line 22
    path('/.well-known/pki-validation/',include('backend.urls'))
       ^
SyntaxError: invalid syntax

During handling of the above exception, another exception occurred:

Traceback (most recent call last):
  File "/usr/local/lib/python3.6/site-packages/django/core/handlers/exception.py", line 35, in inner
    response = get_response(request)
  File "/usr/local/lib/python3.6/site-packages/django/utils/deprecation.py", line 95, in __call__
    response = self.get_response(request)
  File "/usr/local/lib/python3.6/site-packages/django/core/handlers/exception.py", line 37, in inner
    response = response_for_exception(request, exc)
  File "/usr/local/lib/python3.6/site-packages/django/core/handlers/exception.py", line 87, in response_for_exception
    response = handle_uncaught_exception(request, get_resolver(get_urlconf()), sys.exc_info())
  File "/usr/local/lib/python3.6/site-packages/django/core/handlers/exception.py", line 125, in handle_uncaught_exception
    callback, param_dict = resolver.resolve_error_handler(500)
  File "/usr/local/lib/python3.6/site-packages/django/urls/resolvers.py", line 549, in resolve_error_handler
    callback = getattr(self.urlconf_module, 'handler%s' % view_type, None)
  File "/usr/local/lib/python3.6/site-packages/django/utils/functional.py", line 36, in __get__
    res = instance.__dict__[self.name] = self.func(instance)
  File "/usr/local/lib/python3.6/site-packages/django/urls/resolvers.py", line 529, in urlconf_module
    return import_module(self.urlconf_name)
  File "/usr/lib64/python3.6/importlib/__init__.py", line 126, in import_module
    return _bootstrap._gcd_import(name[level:], package, level)
  File "<frozen importlib._bootstrap>", line 994, in _gcd_import
  File "<frozen importlib._bootstrap>", line 971, in _find_and_load
  File "<frozen importlib._bootstrap>", line 955, in _find_and_load_unlocked
  File "<frozen importlib._bootstrap>", line 665, in _load_unlocked
  File "<frozen importlib._bootstrap_external>", line 674, in exec_module
  File "<frozen importlib._bootstrap_external>", line 781, in get_code
  File "<frozen importlib._bootstrap_external>", line 741, in source_to_code
  File "<frozen importlib._bootstrap>", line 219, in _call_with_frames_removed
  File "./dongqiudi/urls.py", line 22
    path('/.well-known/pki-validation/',include('backend.urls'))
       ^
SyntaxError: invalid syntax

During handling of the above exception, another exception occurred:

Traceback (most recent call last):
  File "/usr/local/lib/python3.6/site-packages/django/core/handlers/wsgi.py", line 146, in __call__
    response = self.get_response(request)
  File "/usr/local/lib/python3.6/site-packages/django/core/handlers/base.py", line 81, in get_response
    response = self._middleware_chain(request)
  File "/usr/local/lib/python3.6/site-packages/django/core/handlers/exception.py", line 37, in inner
    response = response_for_exception(request, exc)
  File "/usr/local/lib/python3.6/site-packages/django/core/handlers/exception.py", line 87, in response_for_exception
    response = handle_uncaught_exception(request, get_resolver(get_urlconf()), sys.exc_info())
  File "/usr/local/lib/python3.6/site-packages/django/core/handlers/exception.py", line 125, in handle_uncaught_exception
    callback, param_dict = resolver.resolve_error_handler(500)
  File "/usr/local/lib/python3.6/site-packages/django/urls/resolvers.py", line 549, in resolve_error_handler
    callback = getattr(self.urlconf_module, 'handler%s' % view_type, None)
  File "/usr/local/lib/python3.6/site-packages/django/utils/functional.py", line 36, in __get__
    res = instance.__dict__[self.name] = self.func(instance)
  File "/usr/local/lib/python3.6/site-packages/django/urls/resolvers.py", line 529, in urlconf_module
    return import_module(self.urlconf_name)
  File "/usr/lib64/python3.6/importlib/__init__.py", line 126, in import_module
    return _bootstrap._gcd_import(name[level:], package, level)
  File "<frozen importlib._bootstrap>", line 994, in _gcd_import
  File "<frozen importlib._bootstrap>", line 971, in _find_and_load
  File "<frozen importlib._bootstrap>", line 955, in _find_and_load_unlocked
  File "<frozen importlib._bootstrap>", line 665, in _load_unlocked
  File "<frozen importlib._bootstrap_external>", line 674, in exec_module
  File "<frozen importlib._bootstrap_external>", line 781, in get_code
  File "<frozen importlib._bootstrap_external>", line 741, in source_to_code
  File "<frozen importlib._bootstrap>", line 219, in _call_with_frames_removed
  File "./dongqiudi/urls.py", line 22
    path('/.well-known/pki-validation/',include('backend.urls'))
       ^
SyntaxError: invalid syntax
[pid: 32061|app: 0|req: 2/2] 127.0.0.1 () {36 vars in 511 bytes} [Fri May  8 14:33:20 2020] GET /api/v1.0/slide_show/ => generated 0 bytes in 137 msecs (HTTP/1.0 500) 0 headers in 0 bytes (0 switches on core 0)
Traceback (most recent call last):
  File "/usr/local/lib/python3.6/site-packages/django/core/handlers/exception.py", line 35, in inner
    response = get_response(request)
  File "/usr/local/lib/python3.6/site-packages/django/utils/deprecation.py", line 93, in __call__
    response = self.process_request(request)
  File "/usr/local/lib/python3.6/site-packages/django/middleware/common.py", line 60, in process_request
    if self.should_redirect_with_slash(request):
  File "/usr/local/lib/python3.6/site-packages/django/middleware/common.py", line 78, in should_redirect_with_slash
    not is_valid_path(request.path_info, urlconf) and
  File "/usr/local/lib/python3.6/site-packages/django/urls/base.py", line 155, in is_valid_path
    resolve(path, urlconf)
  File "/usr/local/lib/python3.6/site-packages/django/urls/base.py", line 24, in resolve
    return get_resolver(urlconf).resolve(path)
  File "/usr/local/lib/python3.6/site-packages/django/urls/resolvers.py", line 494, in resolve
    for pattern in self.url_patterns:
  File "/usr/local/lib/python3.6/site-packages/django/utils/functional.py", line 36, in __get__
    res = instance.__dict__[self.name] = self.func(instance)
  File "/usr/local/lib/python3.6/site-packages/django/urls/resolvers.py", line 536, in url_patterns
    patterns = getattr(self.urlconf_module, "urlpatterns", self.urlconf_module)
  File "/usr/local/lib/python3.6/site-packages/django/utils/functional.py", line 36, in __get__
    res = instance.__dict__[self.name] = self.func(instance)
  File "/usr/local/lib/python3.6/site-packages/django/urls/resolvers.py", line 529, in urlconf_module
    return import_module(self.urlconf_name)
  File "/usr/lib64/python3.6/importlib/__init__.py", line 126, in import_module
    return _bootstrap._gcd_import(name[level:], package, level)
  File "<frozen importlib._bootstrap>", line 994, in _gcd_import
  File "<frozen importlib._bootstrap>", line 971, in _find_and_load
  File "<frozen importlib._bootstrap>", line 955, in _find_and_load_unlocked
  File "<frozen importlib._bootstrap>", line 665, in _load_unlocked
  File "<frozen importlib._bootstrap_external>", line 674, in exec_module
  File "<frozen importlib._bootstrap_external>", line 781, in get_code
  File "<frozen importlib._bootstrap_external>", line 741, in source_to_code
  File "<frozen importlib._bootstrap>", line 219, in _call_with_frames_removed
  File "./dongqiudi/urls.py", line 22
    path('/.well-known/pki-validation/',include('backend.urls'))
       ^
SyntaxError: invalid syntax

During handling of the above exception, another exception occurred:

Traceback (most recent call last):
  File "/usr/local/lib/python3.6/site-packages/django/core/handlers/exception.py", line 35, in inner
    response = get_response(request)
  File "/usr/local/lib/python3.6/site-packages/django/utils/deprecation.py", line 95, in __call__
    response = self.get_response(request)
  File "/usr/local/lib/python3.6/site-packages/django/core/handlers/exception.py", line 37, in inner
    response = response_for_exception(request, exc)
  File "/usr/local/lib/python3.6/site-packages/django/core/handlers/exception.py", line 87, in response_for_exception
    response = handle_uncaught_exception(request, get_resolver(get_urlconf()), sys.exc_info())
  File "/usr/local/lib/python3.6/site-packages/django/core/handlers/exception.py", line 125, in handle_uncaught_exception
    callback, param_dict = resolver.resolve_error_handler(500)
  File "/usr/local/lib/python3.6/site-packages/django/urls/resolvers.py", line 549, in resolve_error_handler
    callback = getattr(self.urlconf_module, 'handler%s' % view_type, None)
  File "/usr/local/lib/python3.6/site-packages/django/utils/functional.py", line 36, in __get__
    res = instance.__dict__[self.name] = self.func(instance)
  File "/usr/local/lib/python3.6/site-packages/django/urls/resolvers.py", line 529, in urlconf_module
    return import_module(self.urlconf_name)
  File "/usr/lib64/python3.6/importlib/__init__.py", line 126, in import_module
    return _bootstrap._gcd_import(name[level:], package, level)
  File "<frozen importlib._bootstrap>", line 994, in _gcd_import
  File "<frozen importlib._bootstrap>", line 971, in _find_and_load
  File "<frozen importlib._bootstrap>", line 955, in _find_and_load_unlocked
  File "<frozen importlib._bootstrap>", line 665, in _load_unlocked
  File "<frozen importlib._bootstrap_external>", line 674, in exec_module
  File "<frozen importlib._bootstrap_external>", line 781, in get_code
  File "<frozen importlib._bootstrap_external>", line 741, in source_to_code
  File "<frozen importlib._bootstrap>", line 219, in _call_with_frames_removed
  File "./dongqiudi/urls.py", line 22
    path('/.well-known/pki-validation/',include('backend.urls'))
       ^
SyntaxError: invalid syntax

During handling of the above exception, another exception occurred:

Traceback (most recent call last):
  File "/usr/local/lib/python3.6/site-packages/django/core/handlers/exception.py", line 35, in inner
    response = get_response(request)
  File "/usr/local/lib/python3.6/site-packages/django/utils/deprecation.py", line 95, in __call__
    response = self.get_response(request)
  File "/usr/local/lib/python3.6/site-packages/django/core/handlers/exception.py", line 37, in inner
    response = response_for_exception(request, exc)
  File "/usr/local/lib/python3.6/site-packages/django/core/handlers/exception.py", line 87, in response_for_exception
    response = handle_uncaught_exception(request, get_resolver(get_urlconf()), sys.exc_info())
  File "/usr/local/lib/python3.6/site-packages/django/core/handlers/exception.py", line 125, in handle_uncaught_exception
    callback, param_dict = resolver.resolve_error_handler(500)
  File "/usr/local/lib/python3.6/site-packages/django/urls/resolvers.py", line 549, in resolve_error_handler
    callback = getattr(self.urlconf_module, 'handler%s' % view_type, None)
  File "/usr/local/lib/python3.6/site-packages/django/utils/functional.py", line 36, in __get__
    res = instance.__dict__[self.name] = self.func(instance)
  File "/usr/local/lib/python3.6/site-packages/django/urls/resolvers.py", line 529, in urlconf_module
    return import_module(self.urlconf_name)
  File "/usr/lib64/python3.6/importlib/__init__.py", line 126, in import_module
    return _bootstrap._gcd_import(name[level:], package, level)
  File "<frozen importlib._bootstrap>", line 994, in _gcd_import
  File "<frozen importlib._bootstrap>", line 971, in _find_and_load
  File "<frozen importlib._bootstrap>", line 955, in _find_and_load_unlocked
  File "<frozen importlib._bootstrap>", line 665, in _load_unlocked
  File "<frozen importlib._bootstrap_external>", line 674, in exec_module
  File "<frozen importlib._bootstrap_external>", line 781, in get_code
  File "<frozen importlib._bootstrap_external>", line 741, in source_to_code
  File "<frozen importlib._bootstrap>", line 219, in _call_with_frames_removed
  File "./dongqiudi/urls.py", line 22
    path('/.well-known/pki-validation/',include('backend.urls'))
       ^
SyntaxError: invalid syntax

During handling of the above exception, another exception occurred:

Traceback (most recent call last):
  File "/usr/local/lib/python3.6/site-packages/django/core/handlers/wsgi.py", line 146, in __call__
    response = self.get_response(request)
  File "/usr/local/lib/python3.6/site-packages/django/core/handlers/base.py", line 81, in get_response
    response = self._middleware_chain(request)
  File "/usr/local/lib/python3.6/site-packages/django/core/handlers/exception.py", line 37, in inner
    response = response_for_exception(request, exc)
  File "/usr/local/lib/python3.6/site-packages/django/core/handlers/exception.py", line 87, in response_for_exception
    response = handle_uncaught_exception(request, get_resolver(get_urlconf()), sys.exc_info())
  File "/usr/local/lib/python3.6/site-packages/django/core/handlers/exception.py", line 125, in handle_uncaught_exception
    callback, param_dict = resolver.resolve_error_handler(500)
  File "/usr/local/lib/python3.6/site-packages/django/urls/resolvers.py", line 549, in resolve_error_handler
    callback = getattr(self.urlconf_module, 'handler%s' % view_type, None)
  File "/usr/local/lib/python3.6/site-packages/django/utils/functional.py", line 36, in __get__
    res = instance.__dict__[self.name] = self.func(instance)
  File "/usr/local/lib/python3.6/site-packages/django/urls/resolvers.py", line 529, in urlconf_module
    return import_module(self.urlconf_name)
  File "/usr/lib64/python3.6/importlib/__init__.py", line 126, in import_module
    return _bootstrap._gcd_import(name[level:], package, level)
  File "<frozen importlib._bootstrap>", line 994, in _gcd_import
  File "<frozen importlib._bootstrap>", line 971, in _find_and_load
  File "<frozen importlib._bootstrap>", line 955, in _find_and_load_unlocked
  File "<frozen importlib._bootstrap>", line 665, in _load_unlocked
  File "<frozen importlib._bootstrap_external>", line 674, in exec_module
  File "<frozen importlib._bootstrap_external>", line 781, in get_code
  File "<frozen importlib._bootstrap_external>", line 741, in source_to_code
  File "<frozen importlib._bootstrap>", line 219, in _call_with_frames_removed
  File "./dongqiudi/urls.py", line 22
    path('/.well-known/pki-validation/',include('backend.urls'))
       ^
SyntaxError: invalid syntax
[pid: 32061|app: 0|req: 3/3] 127.0.0.1 () {32 vars in 704 bytes} [Fri May  8 14:34:39 2020] GET //.well-known/pki-validation/fileauth.txt => generated 0 bytes in 46 msecs (HTTP/1.0 500) 0 headers in 0 bytes (0 switches on core 0)
*** Starting uWSGI 2.0.18 (64bit) on [Sat May  9 03:06:24 2020] ***
compiled with version: 8.3.1 20190507 (Red Hat 8.3.1-4) on 04 May 2020 16:35:18
os: Linux-4.18.0-147.5.1.el8_1.x86_64 #1 SMP Wed Feb 5 02:00:39 UTC 2020
nodename: iZ8vb3ysk1dlatpqbiit08Z
machine: x86_64
clock source: unix
detected number of CPU cores: 2
current working directory: /root/jarvis/deployment/dongqiudi
writing pidfile to /root/jarvis/deployment/dongqiudi/pid/uwsgi-8080.pid
detected binary path: /usr/local/bin/uwsgi
!!! no internal routing support, rebuild with pcre support !!!
uWSGI running as root, you can use --uid/--gid/--chroot options
*** WARNING: you are running uWSGI as root !!! (use the --uid flag) *** 
chdir() to /root/jarvis/deployment/dongqiudi
your processes number limit is 15002
your memory page size is 4096 bytes
detected max file descriptor number: 65535
lock engine: pthread robust mutexes
thunder lock: disabled (you can enable it with --thunder-lock)
uwsgi socket 0 bound to UNIX address django.sock fd 9
uWSGI running as root, you can use --uid/--gid/--chroot options
*** WARNING: you are running uWSGI as root !!! (use the --uid flag) *** 
Python version: 3.6.8 (default, Nov 21 2019, 19:31:34)  [GCC 8.3.1 20190507 (Red Hat 8.3.1-4)]
Python main interpreter initialized at 0x17d98d0
uWSGI running as root, you can use --uid/--gid/--chroot options
*** WARNING: you are running uWSGI as root !!! (use the --uid flag) *** 
python threads support enabled
your server socket listen backlog is limited to 100 connections
your mercy for graceful operations on workers is 60 seconds
mapped 145808 bytes (142 KB) for 1 cores
*** Operational MODE: single process ***
{'a': 1}
WSGI app 0 (mountpoint='') ready in 1 seconds on interpreter 0x17d98d0 pid: 2829 (default app)
uWSGI running as root, you can use --uid/--gid/--chroot options
*** WARNING: you are running uWSGI as root !!! (use the --uid flag) *** 
*** uWSGI is running in multiple interpreter mode ***
spawned uWSGI master process (pid: 2829)
spawned uWSGI worker 1 (pid: 2831, cores: 1)
*** Starting uWSGI 2.0.18 (64bit) on [Sat May  9 03:18:11 2020] ***
compiled with version: 8.3.1 20190507 (Red Hat 8.3.1-4) on 04 May 2020 16:35:18
os: Linux-4.18.0-147.5.1.el8_1.x86_64 #1 SMP Wed Feb 5 02:00:39 UTC 2020
nodename: iZ8vb3ysk1dlatpqbiit08Z
machine: x86_64
clock source: unix
detected number of CPU cores: 2
current working directory: /root/jarvis/deployment/dongqiudi
writing pidfile to /root/jarvis/deployment/dongqiudi/pid/uwsgi-8080.pid
detected binary path: /usr/local/bin/uwsgi
!!! no internal routing support, rebuild with pcre support !!!
uWSGI running as root, you can use --uid/--gid/--chroot options
*** WARNING: you are running uWSGI as root !!! (use the --uid flag) *** 
chdir() to /root/jarvis/deployment/dongqiudi
your processes number limit is 15002
your memory page size is 4096 bytes
detected max file descriptor number: 65535
lock engine: pthread robust mutexes
thunder lock: disabled (you can enable it with --thunder-lock)
uwsgi socket 0 bound to UNIX address django.sock fd 9
uWSGI running as root, you can use --uid/--gid/--chroot options
*** WARNING: you are running uWSGI as root !!! (use the --uid flag) *** 
Python version: 3.6.8 (default, Nov 21 2019, 19:31:34)  [GCC 8.3.1 20190507 (Red Hat 8.3.1-4)]
Python main interpreter initialized at 0x17378d0
uWSGI running as root, you can use --uid/--gid/--chroot options
*** WARNING: you are running uWSGI as root !!! (use the --uid flag) *** 
python threads support enabled
your server socket listen backlog is limited to 100 connections
your mercy for graceful operations on workers is 60 seconds
mapped 145808 bytes (142 KB) for 1 cores
*** Operational MODE: single process ***
{'a': 1}
WSGI app 0 (mountpoint='') ready in 0 seconds on interpreter 0x17378d0 pid: 2921 (default app)
uWSGI running as root, you can use --uid/--gid/--chroot options
*** WARNING: you are running uWSGI as root !!! (use the --uid flag) *** 
*** uWSGI is running in multiple interpreter mode ***
spawned uWSGI master process (pid: 2921)
spawned uWSGI worker 1 (pid: 2923, cores: 1)
*** Starting uWSGI 2.0.18 (64bit) on [Sat May  9 03:31:47 2020] ***
compiled with version: 8.3.1 20190507 (Red Hat 8.3.1-4) on 04 May 2020 16:35:18
os: Linux-4.18.0-147.5.1.el8_1.x86_64 #1 SMP Wed Feb 5 02:00:39 UTC 2020
nodename: iZ8vb3ysk1dlatpqbiit08Z
machine: x86_64
clock source: unix
detected number of CPU cores: 2
current working directory: /root/jarvis/deployment/dongqiudi
writing pidfile to /root/jarvis/deployment/dongqiudi/pid/uwsgi-8080.pid
detected binary path: /usr/local/bin/uwsgi
!!! no internal routing support, rebuild with pcre support !!!
uWSGI running as root, you can use --uid/--gid/--chroot options
*** WARNING: you are running uWSGI as root !!! (use the --uid flag) *** 
chdir() to /root/jarvis/deployment/dongqiudi
your processes number limit is 15002
your memory page size is 4096 bytes
detected max file descriptor number: 65535
lock engine: pthread robust mutexes
thunder lock: disabled (you can enable it with --thunder-lock)
uwsgi socket 0 bound to UNIX address django.sock fd 9
uWSGI running as root, you can use --uid/--gid/--chroot options
*** WARNING: you are running uWSGI as root !!! (use the --uid flag) *** 
Python version: 3.6.8 (default, Nov 21 2019, 19:31:34)  [GCC 8.3.1 20190507 (Red Hat 8.3.1-4)]
Python main interpreter initialized at 0xcc18d0
uWSGI running as root, you can use --uid/--gid/--chroot options
*** WARNING: you are running uWSGI as root !!! (use the --uid flag) *** 
python threads support enabled
your server socket listen backlog is limited to 100 connections
your mercy for graceful operations on workers is 60 seconds
mapped 145808 bytes (142 KB) for 1 cores
*** Operational MODE: single process ***
{'a': 1}
WSGI app 0 (mountpoint='') ready in 1 seconds on interpreter 0xcc18d0 pid: 3036 (default app)
uWSGI running as root, you can use --uid/--gid/--chroot options
*** WARNING: you are running uWSGI as root !!! (use the --uid flag) *** 
*** uWSGI is running in multiple interpreter mode ***
spawned uWSGI master process (pid: 3036)
spawned uWSGI worker 1 (pid: 3038, cores: 1)
*** Starting uWSGI 2.0.18 (64bit) on [Sat May  9 03:52:46 2020] ***
compiled with version: 8.3.1 20190507 (Red Hat 8.3.1-4) on 04 May 2020 16:35:18
os: Linux-4.18.0-147.5.1.el8_1.x86_64 #1 SMP Wed Feb 5 02:00:39 UTC 2020
nodename: iZ8vb3ysk1dlatpqbiit08Z
machine: x86_64
clock source: unix
detected number of CPU cores: 2
current working directory: /root/jarvis/deployment/dongqiudi
writing pidfile to /root/jarvis/deployment/dongqiudi/pid/uwsgi-8080.pid
detected binary path: /usr/local/bin/uwsgi
!!! no internal routing support, rebuild with pcre support !!!
uWSGI running as root, you can use --uid/--gid/--chroot options
*** WARNING: you are running uWSGI as root !!! (use the --uid flag) *** 
chdir() to /root/jarvis/deployment/dongqiudi
your processes number limit is 15002
your memory page size is 4096 bytes
detected max file descriptor number: 65535
lock engine: pthread robust mutexes
thunder lock: disabled (you can enable it with --thunder-lock)
uwsgi socket 0 bound to UNIX address django.sock fd 9
uWSGI running as root, you can use --uid/--gid/--chroot options
*** WARNING: you are running uWSGI as root !!! (use the --uid flag) *** 
Python version: 3.6.8 (default, Nov 21 2019, 19:31:34)  [GCC 8.3.1 20190507 (Red Hat 8.3.1-4)]
Python main interpreter initialized at 0x11648d0
uWSGI running as root, you can use --uid/--gid/--chroot options
*** WARNING: you are running uWSGI as root !!! (use the --uid flag) *** 
python threads support enabled
your server socket listen backlog is limited to 100 connections
your mercy for graceful operations on workers is 60 seconds
mapped 145808 bytes (142 KB) for 1 cores
*** Operational MODE: single process ***
{'a': 1}
WSGI app 0 (mountpoint='') ready in 0 seconds on interpreter 0x11648d0 pid: 3205 (default app)
uWSGI running as root, you can use --uid/--gid/--chroot options
*** WARNING: you are running uWSGI as root !!! (use the --uid flag) *** 
*** uWSGI is running in multiple interpreter mode ***
spawned uWSGI master process (pid: 3205)
spawned uWSGI worker 1 (pid: 3207, cores: 1)
